2017-11-28 17:39:32,294 MainProcess __main__ ERROR    Exception on /v1/books [GET]
Traceback (most recent call last):
  File "/Users/aarteekasliwal/.pyenv/versions/3.6.3/lib/python3.6/site-packages/flask/app.py", line 1982, in wsgi_app
    response = self.full_dispatch_request()
  File "/Users/aarteekasliwal/.pyenv/versions/3.6.3/lib/python3.6/site-packages/flask/app.py", line 1614, in full_dispatch_request
    rv = self.handle_user_exception(e)
  File "/Users/aarteekasliwal/.pyenv/versions/3.6.3/lib/python3.6/site-packages/flask/app.py", line 1517, in handle_user_exception
    reraise(exc_type, exc_value, tb)
  File "/Users/aarteekasliwal/.pyenv/versions/3.6.3/lib/python3.6/site-packages/flask/_compat.py", line 33, in reraise
    raise value
  File "/Users/aarteekasliwal/.pyenv/versions/3.6.3/lib/python3.6/site-packages/flask/app.py", line 1612, in full_dispatch_request
    rv = self.dispatch_request()
  File "/Users/aarteekasliwal/.pyenv/versions/3.6.3/lib/python3.6/site-packages/flask/app.py", line 1598, in dispatch_request
    return self.view_functions[rule.endpoint](**req.view_args)
  File "server.py", line 35, in get_books
    response = client.get_all()
  File "/Users/aarteekasliwal/Documents/281-Project/productCatalogPythonServer/client.py", line 33, in get_all
    return json.dumps({"Status": "OK", "data": output})
  File "/Users/aarteekasliwal/.pyenv/versions/3.6.3/lib/python3.6/json/__init__.py", line 231, in dumps
    return _default_encoder.encode(obj)
  File "/Users/aarteekasliwal/.pyenv/versions/3.6.3/lib/python3.6/json/encoder.py", line 199, in encode
    chunks = self.iterencode(o, _one_shot=True)
  File "/Users/aarteekasliwal/.pyenv/versions/3.6.3/lib/python3.6/json/encoder.py", line 257, in iterencode
    return _iterencode(o, 0)
  File "/Users/aarteekasliwal/.pyenv/versions/3.6.3/lib/python3.6/json/encoder.py", line 180, in default
    o.__class__.__name__)
TypeError: Object of type 'Cursor' is not JSON serializable
